<?xml version="1.0" ?>
<!-- =================================================================================== -->
<!-- |    This document was autogenerated by xacro from /home/swarm/rover_simulator2/src/rover_description/urdf/p3at.urdf.xacro | -->
<!-- |    EDITING THIS FILE BY HAND IS NOT RECOMMENDED                                 | -->
<!-- =================================================================================== -->

<!-- <link name="base_link">
    <visual>
      <geometry>
        <cylinder length="0.6" radius="0.2"/>
      </geometry>
      <material name="blue"/>
    </visual>
    <collision>
      <geometry>
        <cylinder length="0.6" radius="0.2"/>
      </geometry>
    </collision>
  </link> -->
<robot name="rover" xmlns:controller="http://playerstage.sourceforge.net/gazebo/xmlschema/#controller" xmlns:interface="http://playerstage.sourceforge.net/gazebo/xmlschema/#interface" xmlns:sensor="http://playerstage.sourceforge.net/gazebo/xmlschema/#sensor" xmlns:xacro="http://ros.org/wiki/xacro">
  <link name="base_link"/>
  <!-- Chassis -->
  <link name="chassis">
    <inertial>
      <mass value="20.0"/>
      <origin xyz="0 0 -0.090"/>
      <inertia ixx="0.3338" ixy="0.0" ixz="0.0" iyy="0.4783" iyz="0.0" izz="0.3338"/>
    </inertial>
    <visual>
      <origin rpy="0 0 0" xyz="0 0 0.0"/>
      <geometry name="pioneer_geom">
        <mesh filename="$(find sando)/meshes/chassis.dae"/>
      </geometry>
    </visual>
    <collision>
      <origin rpy="0 0 0" xyz="0 0 0.0"/>
      <geometry>
        <mesh filename="$(find sando)/meshes/chassis.dae"/>
      </geometry>
    </collision>
  </link>
  <gazebo reference="chassis">
    <material value="Gazebo/Red"/>
  </gazebo>
  <joint name="base_chassis_joint" type="fixed">
    <origin rpy="0 0 0" xyz="0.00 0 0.177"/>
    <parent link="base_link"/>
    <child link="chassis"/>
  </joint>
  <!-- Top -->
  <link name="top_plate">
    <inertial>
      <mass value="0.1"/>
      <origin xyz="-0.025 0 -0.223"/>
      <inertia ixx="1.0" ixy="0.0" ixz="0.0" iyy="1.0" iyz="0.0" izz="1.0"/>
    </inertial>
    <visual>
      <origin rpy="0 0 0" xyz="0 0 0"/>
      <geometry name="pioneer_geom">
        <mesh filename="$(find sando)/meshes/top.dae"/>
      </geometry>
      <material name="TopBlack">
        <color rgba="0.038 0.038 0.038 1.0"/>
      </material>
    </visual>
    <collision>
      <origin rpy="0 0 0" xyz="0 0 0"/>
      <geometry>
        <box size="0 0 0"/>
      </geometry>
    </collision>
  </link>
  <gazebo reference="top_plate">
    <material value="Gazebo/Black"/>
  </gazebo>
  <joint name="chassis_top_joint" type="fixed">
    <origin rpy="0 0 0" xyz="0.043 0 0.254"/>
    <parent link="base_link"/>
    <child link="top_plate"/>
  </joint>
  <link name="p3at_front_left_axle">
    <inertial>
      <mass value="0.1"/>
      <origin xyz="0 0 0"/>
      <inertia ixx="1.0" ixy="0.0" ixz="0.0" iyy="1.0" iyz="0.0" izz="1.0"/>
    </inertial>
    <visual>
      <origin rpy="0 0 0" xyz="0 0 0"/>
      <geometry name="pioneer_geom">
        <mesh filename="$(find sando)/meshes/axle.dae"/>
      </geometry>
      <material name="AxleGrey">
        <color rgba="0.5 0.5 0.5 1"/>
      </material>
    </visual>
    <collision>
      <origin rpy="0 0 0" xyz="0 0 0"/>
      <geometry>
        <box size="0 0 0"/>
      </geometry>
    </collision>
  </link>
  <gazebo reference="p3at_front_left_axle">
    <material value="Gazebo/Grey"/>
  </gazebo>
  <joint name="base_front_left_axle_joint" type="fixed">
    <origin rpy="0 0 0" xyz="0.135 0.156 0.111"/>
    <parent link="base_link"/>
    <child link="p3at_front_left_axle"/>
  </joint>
  <link name="p3at_front_left_hub">
    <inertial>
      <mass value="0.1"/>
      <origin xyz="0 0 0"/>
      <inertia ixx="1.0" ixy="0.0" ixz="0.0" iyy="1.0" iyz="0.0" izz="1.0"/>
    </inertial>
    <visual>
      <origin rpy="0 0 0" xyz="0 0 0"/>
      <geometry name="pioneer_geom">
        <mesh filename="$(find sando)/meshes/left_hubcap.dae"/>
      </geometry>
      <material name="HubcapYellow">
        <color rgba="1.0 0.811 0.151 1.0"/>
      </material>
    </visual>
    <collision>
      <origin rpy="0 0 0" xyz="0 0 0"/>
      <geometry>
        <box size="0 0 0"/>
      </geometry>
    </collision>
  </link>
  <gazebo reference="p3at_front_left_hub">
    <material value="Gazebo/Yellow"/>
  </gazebo>
  <joint name="base_front_left_hub_joint" type="fixed">
    <origin rpy="0 0 0" xyz="0 0.041 0"/>
    <parent link="p3at_front_left_axle"/>
    <child link="p3at_front_left_hub"/>
  </joint>
  <link name="p3at_front_left_wheel">
    <inertial>
      <mass value="0.5"/>
      <origin xyz="0 0 0"/>
      <inertia ixx="0.012411765597" ixy="0" ixz="0" iyy="0.015218160428" iyz="0" izz="0.011763977943"/>
    </inertial>
    <visual>
      <origin rpy="0 0 0" xyz="0 0 0"/>
      <geometry name="pioneer_geom">
        <mesh filename="$(find sando)/meshes/left_wheel.dae"/>
      </geometry>
      <material name="WheelBlack">
        <color rgba="0.117 0.117 0.117 1"/>
      </material>
    </visual>
    <collision>
      <origin rpy="-1.57079635 0 0" xyz="0 0 0"/>
      <geometry>
        <!--mesh filename="$(find sando)/meshes/wheel.dae"/-->
        <cylinder length="0.035" radius="0.110"/>
      </geometry>
    </collision>
  </link>
  <gazebo reference="p3at_front_left_wheel">
    <material value="Gazebo/Black"/>
  </gazebo>
  <joint name="p3at_front_left_wheel_joint" type="continuous">
    <axis xyz="0 1 0"/>
    <anchor xyz="0 0 0"/>
    <limit effort="100" velocity="100"/>
    <joint_properties damping="0.7"/>
    <origin rpy="0 0 0" xyz="0 0 0"/>
    <parent link="p3at_front_left_hub"/>
    <child link="p3at_front_left_wheel"/>
  </joint>
  <link name="p3at_front_right_axle">
    <inertial>
      <mass value="0.1"/>
      <origin xyz="0 0 0"/>
      <inertia ixx="1.0" ixy="0.0" ixz="0.0" iyy="1.0" iyz="0.0" izz="1.0"/>
    </inertial>
    <visual>
      <origin rpy="0 0 0" xyz="0 0 0"/>
      <geometry name="pioneer_geom">
        <mesh filename="$(find sando)/meshes/axle.dae"/>
      </geometry>
      <material name="AxleGrey">
        <color rgba="0.5 0.5 0.5 1"/>
      </material>
    </visual>
    <collision>
      <origin rpy="0 0 0" xyz="0 0 0"/>
      <geometry>
        <box size="0 0 0"/>
      </geometry>
    </collision>
  </link>
  <gazebo reference="p3at_front_right_axle">
    <material value="Gazebo/Grey"/>
  </gazebo>
  <joint name="base_front_right_axle_joint" type="fixed">
    <origin rpy="0 0 0" xyz="0.135 -0.156 0.111"/>
    <parent link="base_link"/>
    <child link="p3at_front_right_axle"/>
  </joint>
  <link name="p3at_front_right_hub">
    <inertial>
      <mass value="0.1"/>
      <origin xyz="0 0 0"/>
      <inertia ixx="1.0" ixy="0.0" ixz="0.0" iyy="1.0" iyz="0.0" izz="1.0"/>
    </inertial>
    <visual>
      <origin rpy="0 0 0" xyz="0 0 0"/>
      <geometry name="pioneer_geom">
        <mesh filename="$(find sando)/meshes/right_hubcap.dae"/>
      </geometry>
      <material name="HubcapYellow">
        <color rgba="1.0 0.811 0.151 1.0"/>
      </material>
    </visual>
    <collision>
      <origin rpy="0 0 0" xyz="0 0 0"/>
      <geometry>
        <box size="0 0 0"/>
      </geometry>
    </collision>
  </link>
  <gazebo reference="p3at_front_right_hub">
    <material value="Gazebo/Yellow"/>
  </gazebo>
  <joint name="base_front_right_hub_joint" type="fixed">
    <origin rpy="0 0 0" xyz="0 -0.041 0"/>
    <parent link="p3at_front_right_axle"/>
    <child link="p3at_front_right_hub"/>
  </joint>
  <link name="p3at_front_right_wheel">
    <inertial>
      <mass value="0.5"/>
      <origin xyz="0 0 0"/>
      <inertia ixx="0.012411765597" ixy="0" ixz="0" iyy="0.015218160428" iyz="0" izz="0.011763977943"/>
    </inertial>
    <visual>
      <origin rpy="0 0 0" xyz="0 0 0"/>
      <geometry name="pioneer_geom">
        <mesh filename="$(find sando)/meshes/right_wheel.dae"/>
      </geometry>
      <material name="WheelBlack">
        <color rgba="0.117 0.117 0.117 1"/>
      </material>
    </visual>
    <collision>
      <origin rpy="-1.57079635 0 0" xyz="0 0 0"/>
      <geometry>
        <!--mesh filename="$(find sando)/meshes/wheel.dae"/-->
        <cylinder length="0.035" radius="0.110"/>
      </geometry>
    </collision>
  </link>
  <gazebo reference="p3at_front_right_wheel">
    <material value="Gazebo/Black"/>
  </gazebo>
  <joint name="p3at_front_right_wheel_joint" type="continuous">
    <axis xyz="0 1 0"/>
    <anchor xyz="0 0 0"/>
    <limit effort="100" velocity="100"/>
    <joint_properties damping="0.7"/>
    <origin rpy="0 0 0" xyz="0 0 0"/>
    <parent link="p3at_front_right_hub"/>
    <child link="p3at_front_right_wheel"/>
  </joint>
  <link name="p3at_back_left_axle">
    <inertial>
      <mass value="0.1"/>
      <origin xyz="0 0 0"/>
      <inertia ixx="1.0" ixy="0.0" ixz="0.0" iyy="1.0" iyz="0.0" izz="1.0"/>
    </inertial>
    <visual>
      <origin rpy="0 0 0" xyz="0 0 0"/>
      <geometry name="pioneer_geom">
        <mesh filename="$(find sando)/meshes/axle.dae"/>
      </geometry>
      <material name="AxleGrey">
        <color rgba="0.5 0.5 0.5 1"/>
      </material>
    </visual>
    <collision>
      <origin rpy="0 0 0" xyz="0 0 0"/>
      <geometry>
        <mesh filename="$(find sando)/meshes/axle.dae"/>
      </geometry>
    </collision>
  </link>
  <gazebo reference="p3at_back_left_axle">
    <material value="Gazebo/Grey"/>
  </gazebo>
  <joint name="bp3at_back_left_axle_joint" type="fixed">
    <origin rpy="0 0 0" xyz="-0.134 0.156 0.111"/>
    <parent link="base_link"/>
    <child link="p3at_back_left_axle"/>
  </joint>
  <link name="p3at_back_left_hub">
    <inertial>
      <mass value="0.1"/>
      <origin xyz="0 0 0"/>
      <inertia ixx="1.0" ixy="0.0" ixz="0.0" iyy="1.0" iyz="0.0" izz="1.0"/>
    </inertial>
    <visual>
      <origin rpy="0 0 0" xyz="0 0 0"/>
      <geometry name="pioneer_geom">
        <mesh filename="$(find sando)/meshes/left_hubcap.dae"/>
      </geometry>
      <material name="HubcapYellow"/>
    </visual>
    <collision>
      <origin rpy="0 0 0" xyz="0 0 0"/>
      <geometry>
        <mesh filename="$(find sando)/meshes/left_hubcap.dae"/>
      </geometry>
    </collision>
  </link>
  <gazebo reference="p3at_back_left_hub">
    <material value="Gazebo/Yellow"/>
  </gazebo>
  <joint name="p3at_back_left_hub_joint" type="fixed">
    <origin rpy="0 0 0" xyz="-0 0.041 0"/>
    <parent link="p3at_back_left_axle"/>
    <child link="p3at_back_left_hub"/>
  </joint>
  <link name="p3at_back_left_wheel">
    <inertial>
      <mass value="0.5"/>
      <origin xyz="0 0 0"/>
      <inertia ixx="0.012411765597" ixy="0" ixz="0" iyy="0.015218160428" iyz="0" izz="0.011763977943"/>
    </inertial>
    <visual>
      <origin rpy="0 0 0" xyz="0 0 0"/>
      <geometry name="pioneer_geom">
        <mesh filename="$(find sando)/meshes/left_wheel.dae"/>
      </geometry>
      <material name="WheelBlack"/>
    </visual>
    <collision>
      <origin rpy="-1.57079635 0 0" xyz="0 0 0"/>
      <geometry>
        <!--mesh filename="$(find sando)/meshes/wheel.dae"/-->
        <cylinder length="0.035" radius="0.110"/>
      </geometry>
    </collision>
  </link>
  <gazebo reference="p3at_back_left_wheel">
    <material value="Gazebo/Black"/>
  </gazebo>
  <joint name="p3at_back_left_wheel_joint" type="continuous">
    <axis xyz="0 1 0"/>
    <anchor xyz="0 0 0"/>
    <limit effort="100" velocity="100"/>
    <joint_properties damping="0.7"/>
    <origin rpy="0 0 0" xyz="0 0 0"/>
    <parent link="p3at_back_left_hub"/>
    <child link="p3at_back_left_wheel"/>
  </joint>
  <gazebo reference="p3at_back_left_wheel">
    <kp>1000000.0</kp>
    <!-- kp and kd for rubber -->
    <kd>100.0</kd>
    <mu1>10.0</mu1>
    <mu2>1.0</mu2>
    <fdir1>1 0 0</fdir1>
    <!-- is this correct? -->
    <maxVel>1.0</maxVel>
    <minDepth>0.00</minDepth>
  </gazebo>
  <gazebo reference="p3at_front_left_wheel">
    <kp>1000000.0</kp>
    <!-- kp and kd for rubber -->
    <kd>100.0</kd>
    <mu1>10.0</mu1>
    <mu2>1.0</mu2>
    <fdir1>1 0 0</fdir1>
    <!-- is this correct? -->
    <maxVel>1.0</maxVel>
    <minDepth>0.00</minDepth>
  </gazebo>
  <link name="p3at_back_right_axle">
    <inertial>
      <mass value="0.1"/>
      <origin xyz="0 0 0"/>
      <inertia ixx="1.0" ixy="0.0" ixz="0.0" iyy="1.0" iyz="0.0" izz="1.0"/>
    </inertial>
    <visual>
      <origin rpy="0 0 0" xyz="0 0 0"/>
      <geometry name="pioneer_geom">
        <mesh filename="$(find sando)/meshes/axle.dae"/>
      </geometry>
      <material name="AxleGrey">
        <color rgba="0.5 0.5 0.5 1"/>
      </material>
    </visual>
    <collision>
      <origin rpy="0 0 0" xyz="0 0 0"/>
      <geometry>
        <mesh filename="$(find sando)/meshes/axle.dae"/>
      </geometry>
    </collision>
  </link>
  <gazebo reference="p3at_back_right_axle">
    <material value="Gazebo/Grey"/>
  </gazebo>
  <joint name="bp3at_back_right_axle_joint" type="fixed">
    <origin rpy="0 0 0" xyz="-0.134 -0.156 0.111"/>
    <parent link="base_link"/>
    <child link="p3at_back_right_axle"/>
  </joint>
  <link name="p3at_back_right_hub">
    <inertial>
      <mass value="0.1"/>
      <origin xyz="0 0 0"/>
      <inertia ixx="1.0" ixy="0.0" ixz="0.0" iyy="1.0" iyz="0.0" izz="1.0"/>
    </inertial>
    <visual>
      <origin rpy="0 0 0" xyz="0 0 0"/>
      <geometry name="pioneer_geom">
        <mesh filename="$(find sando)/meshes/right_hubcap.dae"/>
      </geometry>
      <material name="HubcapYellow"/>
    </visual>
    <collision>
      <origin rpy="0 0 0" xyz="0 0 0"/>
      <geometry>
        <mesh filename="$(find sando)/meshes/right_hubcap.dae"/>
      </geometry>
    </collision>
  </link>
  <gazebo reference="p3at_back_right_hub">
    <material value="Gazebo/Yellow"/>
  </gazebo>
  <joint name="p3at_back_right_hub_joint" type="fixed">
    <origin rpy="0 0 0" xyz="-0 -0.041 0"/>
    <parent link="p3at_back_right_axle"/>
    <child link="p3at_back_right_hub"/>
  </joint>
  <link name="p3at_back_right_wheel">
    <inertial>
      <mass value="0.5"/>
      <origin xyz="0 0 0"/>
      <inertia ixx="0.012411765597" ixy="0" ixz="0" iyy="0.015218160428" iyz="0" izz="0.011763977943"/>
    </inertial>
    <visual>
      <origin rpy="0 0 0" xyz="0 0 0"/>
      <geometry name="pioneer_geom">
        <mesh filename="$(find sando)/meshes/right_wheel.dae"/>
      </geometry>
      <material name="WheelBlack"/>
    </visual>
    <collision>
      <origin rpy="-1.57079635 0 0" xyz="0 0 0"/>
      <geometry>
        <!--mesh filename="$(find sando)/meshes/wheel.dae"/-->
        <cylinder length="0.035" radius="0.110"/>
      </geometry>
    </collision>
  </link>
  <gazebo reference="p3at_back_right_wheel">
    <material value="Gazebo/Black"/>
  </gazebo>
  <joint name="p3at_back_right_wheel_joint" type="continuous">
    <axis xyz="0 1 0"/>
    <anchor xyz="0 0 0"/>
    <limit effort="100" velocity="100"/>
    <joint_properties damping="0.7"/>
    <origin rpy="0 0 0" xyz="0 0 0"/>
    <parent link="p3at_back_right_hub"/>
    <child link="p3at_back_right_wheel"/>
  </joint>
  <gazebo reference="p3at_back_right_wheel">
    <kp>1000000.0</kp>
    <!-- kp and kd for rubber -->
    <kd>100.0</kd>
    <mu1>10.0</mu1>
    <mu2>1.0</mu2>
    <fdir1>1 0 0</fdir1>
    <!-- is this correct? -->
    <maxVel>1.0</maxVel>
    <minDepth>0.00</minDepth>
  </gazebo>
  <gazebo reference="p3at_front_right_wheel">
    <kp>1000000.0</kp>
    <!-- kp and kd for rubber -->
    <kd>100.0</kd>
    <mu1>10.0</mu1>
    <mu2>1.0</mu2>
    <fdir1>1 0 0</fdir1>
    <!-- is this correct? -->
    <maxVel>1.0</maxVel>
    <minDepth>0.00</minDepth>
  </gazebo>
  <gazebo>
    <plugin filename="libgazebo_ros_joint_state_publisher.so" name="joint_state_publisher">
      <robotNamespace/>
      <jointName>p3at_front_left_wheel_joint, p3at_front_right_wheel_joint, p3at_back_left_wheel_joint, p3at_back_right_wheel_joint</jointName>
      <updateRate>10.0</updateRate>
      <alwaysOn>true</alwaysOn>
    </plugin>
  </gazebo>
  <gazebo>
    <plugin filename="librover_gazebo_noisy_skid_steer_drive.so" name="skid_steer_drive_controller">
      <updateRate>50</updateRate>
      <!-- <robotNamespace>/</robotNamespace> -->
      <leftFrontJoint>p3at_front_left_wheel_joint</leftFrontJoint>
      <rightFrontJoint>p3at_front_right_wheel_joint</rightFrontJoint>
      <leftRearJoint>p3at_back_left_wheel_joint</leftRearJoint>
      <rightRearJoint>p3at_back_right_wheel_joint</rightRearJoint>
      <wheelSeparation>0.4</wheelSeparation>
      <wheelDiameter>0.220</wheelDiameter>
      <wheel_accel>1.8</wheel_accel>
      <torque>5</torque>
      <commandTopic>cmd_vel</commandTopic>
      <poseTopic>pose</poseTopic>
      <resetOdomTopic>reset_odom</resetOdomTopic>
      <odometryTrueTopic>odom_true</odometryTrueTopic>
      <odometryTopic>odom</odometryTopic>
      <robotBaseFrame>base_link</robotBaseFrame>
      <odometryFrame>odom</odometryFrame>
      <broadcastTF>true</broadcastTF>
      <covariance_v>0.1</covariance_v>
      <covariance_w>0.01</covariance_w>
      <alpha1>0.001</alpha1>
      <alpha2>0.0005</alpha2>
      <alpha3>0.0005</alpha3>
      <alpha4>0.001</alpha4>
    </plugin>
  </gazebo>
  <!-- Hokuyo Laser -->
  <joint name="laser_joint" type="fixed">
    <axis xyz="0 1 0"/>
    <origin rpy="0 0 3.14159" xyz="0.1397 0 0.1778"/>
    <parent link="top_plate"/>
    <child link="laser_link"/>
  </joint>
  <link name="laser_link">
    <collision>
      <origin rpy="0 0 0" xyz="0 0 0"/>
      <geometry>
        <box size="0.01 0.01 0.01"/>
      </geometry>
    </collision>
    <visual>
      <origin rpy="0 0 0" xyz="0 0 0"/>
      <geometry>
        <mesh filename="$(find sando)/meshes/hokuyo1.dae"/>
      </geometry>
    </visual>
    <inertial>
      <mass value="1e-5"/>
      <origin rpy="0 0 0" xyz="0 0 0"/>
      <inertia ixx="1e-6" ixy="0" ixz="0" iyy="1e-6" iyz="0" izz="1e-6"/>
    </inertial>
  </link>
  <gazebo reference="laser_link">
    <sensor name="head_rplidar_sensor" type="ray">
      <pose>0 0 0.06 0 0 0</pose>
      <visualize>true</visualize>
      <update_rate>40</update_rate>
      <ray>
        <scan>
          <horizontal>
            <samples>720</samples>
            <resolution>1</resolution>
            <min_angle>-3.14159265</min_angle>
            <max_angle>3.14159265</max_angle>
          </horizontal>
        </scan>
        <range>
          <min>0.15</min>
          <max>12.0</max>
          <resolution>0.01</resolution>
        </range>
        <noise>
          <type>gaussian</type>
          <!-- Noise parameters based on published spec for Hokuyo laser
               achieving "+-30mm" accuracy at range < 10m.  A mean of 0.0m and
               stddev of 0.01m will put 99.7% of samples within 0.03m of the true
               reading. -->
          <mean>0.0</mean>
          <stddev>0.01</stddev>
        </noise>
      </ray>
      <plugin filename="libgazebo_ros_laser.so" name="gazebo_ros_head_hokuyo_controller">
        <topicName>/scan</topicName>
        <frameName>laser_link</frameName>
      </plugin>
    </sensor>
  </gazebo>
  <!--
<gazebo>
    <plugin name="imu_controller" filename="libhector_gazebo_ros_imu.so">
        <robotNamespace>/</robotNamespace>
        <updateRate>50.0</updateRate>
        <bodyName>imu</bodyName>
        <topicName>imu/data_raw</topicName>
        <accelDrift>0.05 0.05 0.05</accelDrift>
        <accelGaussianNoise>0.05 0.05 0.05</accelGaussianNoise>
        <rateDrift>0.05 0.05 0.05 </rateDrift>
        <rateGaussianNoise>0.05 0.05 0.05 </rateGaussianNoise>
        <headingDrift>0.05</headingDrift>
        <headingGaussianNoise>0.05</headingGaussianNoise>
    </plugin>
</gazebo>
-->
</robot>
